Traceback (most recent call last):
  File "C:\laragon\bin\python\python-3.10\lib\site-packages\jupyter_core\utils\__init__.py", line 154, in wrapped
    asyncio.get_running_loop()
RuntimeError: no running event loop

During handling of the above exception, another exception occurred:

Traceback (most recent call last):
  File "C:\laragon\bin\python\python-3.10\lib\site-packages\jupyter_cache\executors\utils.py", line 58, in single_nb_execution
    executenb(
  File "C:\laragon\bin\python\python-3.10\lib\site-packages\nbclient\client.py", line 1319, in execute
    return NotebookClient(nb=nb, resources=resources, km=km, **kwargs).execute()
  File "C:\laragon\bin\python\python-3.10\lib\site-packages\jupyter_core\utils\__init__.py", line 158, in wrapped
    return loop.run_until_complete(inner)
  File "C:\laragon\bin\python\python-3.10\lib\asyncio\base_events.py", line 646, in run_until_complete
    return future.result()
  File "C:\laragon\bin\python\python-3.10\lib\site-packages\nbclient\client.py", line 709, in async_execute
    await self.async_execute_cell(
  File "C:\laragon\bin\python\python-3.10\lib\site-packages\nbclient\client.py", line 1062, in async_execute_cell
    await self._check_raise_for_error(cell, cell_index, exec_reply)
  File "C:\laragon\bin\python\python-3.10\lib\site-packages\nbclient\client.py", line 918, in _check_raise_for_error
    raise CellExecutionError.from_cell_and_msg(cell, exec_reply_content)
nbclient.exceptions.CellExecutionError: An error occurred while executing the following cell:
------------------
# URL homepage CNN Indonesia
url = "https://www.cnnindonesia.com/"
headers = {"User-Agent": "Mozilla/5.0 (Windows NT 10.0; Win64; x64) AppleWebKit/537.36 (KHTML, like Gecko) Chrome/140.0.0.0 Safari/537.36 Edg/140.0.0.0"}

# Ambil halaman utama
response = requests.get(url, headers=headers)
soup = BeautifulSoup(response.text, "html.parser")

data = []

# Loop semua link artikel di homepage
for artikel in soup.select("article a"):
    link = artikel.get("href")
    judul = artikel.get_text(strip=True)

    # Skip jika link kosong atau bukan http
    if not link or not link.startswith("http"):
        continue

    try:
        # Ambil halaman detail berita
        resp_detail = requests.get(link, headers=headers)
        soup_detail = BeautifulSoup(resp_detail.text, "html.parser")

        # --- PERUBAHAN DIMULAI DI SINI ---
        
        # Ambil ID Berita dari link
        id_berita = None
        try:
            # Contoh path: /ekonomi/20250910153012-92-1234567/nama-artikel
            # Kita ambil bagian sebelum nama artikel, yaitu '20250910153012-92-1234567'
            id_segment = link.split("/")[-2]
            # Kemudian kita pisah dengan '-' dan ambil bagian terakhirnya
            id_berita = id_segment.split("-")[-1]
        except (IndexError, AttributeError):
            # Jika struktur URL berbeda dan gagal, ID akan tetap None
            id_berita = None

        # Ambil kategori dari link (path pertama setelah domain)
        kategori = None
        try:
            path = link.replace("https://www.cnnindonesia.com/", "")
            kategori = path.split("/")[0] if path else None
        except Exception:
            kategori = None

        # Ambil isi berita
        paragraf = [p.get_text(strip=True) for p in soup_detail.select("div.detail-text p")]
        isi = " ".join(paragraf)

        if isi:  # hanya simpan kalau ada isi berita
            data.append({
                "id_berita": id_berita, # <-- Kolom baru ditambahkan di sini
                "judul": judul,
                "kategori": kategori,
                "isi": isi,
                "link": link
            })
            
        # --- PERUBAHAN SELESAI DI SINI ---

    except Exception as e:
        print(f"Gagal ambil {link}: {e}")

# Simpan ke dataframe Pandas
df = pd.DataFrame(data)

# Simpan ke file CSV
df.to_csv("berita_cnn_dengan_id.csv", index=False, encoding="utf-8-sig")

# Tampilkan hasil di notebook
pd.set_option("display.max_colwidth", 100)  # biar isi tidak kepotong
print("Proses scraping selesai. Berikut adalah contoh datanya:")
display(df)
------------------


[1;31m---------------------------------------------------------------------------[0m
[1;31mRemoteDisconnected[0m                        Traceback (most recent call last)
File [1;32mC:\laragon\bin\python\python-3.10\lib\site-packages\urllib3\connectionpool.py:787[0m, in [0;36mHTTPConnectionPool.urlopen[1;34m(self, method, url, body, headers, retries, redirect, assert_same_host, timeout, pool_timeout, release_conn, chunked, body_pos, preload_content, decode_content, **response_kw)[0m
[0;32m    786[0m [38;5;66;03m# Make the request on the HTTPConnection object[39;00m
[1;32m--> 787[0m response [38;5;241m=[39m [38;5;28mself[39m[38;5;241m.[39m_make_request(
[0;32m    788[0m     conn,
[0;32m    789[0m     method,
[0;32m    790[0m     url,
[0;32m    791[0m     timeout[38;5;241m=[39mtimeout_obj,
[0;32m    792[0m     body[38;5;241m=[39mbody,
[0;32m    793[0m     headers[38;5;241m=[39mheaders,
[0;32m    794[0m     chunked[38;5;241m=[39mchunked,
[0;32m    795[0m     retries[38;5;241m=[39mretries,
[0;32m    796[0m     response_conn[38;5;241m=[39mresponse_conn,
[0;32m    797[0m     preload_content[38;5;241m=[39mpreload_content,
[0;32m    798[0m     decode_content[38;5;241m=[39mdecode_content,
[0;32m    799[0m     [38;5;241m*[39m[38;5;241m*[39mresponse_kw,
[0;32m    800[0m )
[0;32m    802[0m [38;5;66;03m# Everything went great![39;00m

File [1;32mC:\laragon\bin\python\python-3.10\lib\site-packages\urllib3\connectionpool.py:534[0m, in [0;36mHTTPConnectionPool._make_request[1;34m(self, conn, method, url, body, headers, retries, timeout, chunked, response_conn, preload_content, decode_content, enforce_content_length)[0m
[0;32m    533[0m [38;5;28;01mtry[39;00m:
[1;32m--> 534[0m     response [38;5;241m=[39m [43mconn[49m[38;5;241;43m.[39;49m[43mgetresponse[49m[43m([49m[43m)[49m
[0;32m    535[0m [38;5;28;01mexcept[39;00m (BaseSSLError, [38;5;167;01mOSError[39;00m) [38;5;28;01mas[39;00m e:

File [1;32mC:\laragon\bin\python\python-3.10\lib\site-packages\urllib3\connection.py:565[0m, in [0;36mHTTPConnection.getresponse[1;34m(self)[0m
[0;32m    564[0m [38;5;66;03m# Get the response from http.client.HTTPConnection[39;00m
[1;32m--> 565[0m httplib_response [38;5;241m=[39m [38;5;28;43msuper[39;49m[43m([49m[43m)[49m[38;5;241;43m.[39;49m[43mgetresponse[49m[43m([49m[43m)[49m
[0;32m    567[0m [38;5;28;01mtry[39;00m:

File [1;32mC:\laragon\bin\python\python-3.10\lib\http\client.py:1374[0m, in [0;36mHTTPConnection.getresponse[1;34m(self)[0m
[0;32m   1373[0m [38;5;28;01mtry[39;00m:
[1;32m-> 1374[0m     [43mresponse[49m[38;5;241;43m.[39;49m[43mbegin[49m[43m([49m[43m)[49m
[0;32m   1375[0m [38;5;28;01mexcept[39;00m [38;5;167;01mConnectionError[39;00m:

File [1;32mC:\laragon\bin\python\python-3.10\lib\http\client.py:318[0m, in [0;36mHTTPResponse.begin[1;34m(self)[0m
[0;32m    317[0m [38;5;28;01mwhile[39;00m [38;5;28;01mTrue[39;00m:
[1;32m--> 318[0m     version, status, reason [38;5;241m=[39m [38;5;28;43mself[39;49m[38;5;241;43m.[39;49m[43m_read_status[49m[43m([49m[43m)[49m
[0;32m    319[0m     [38;5;28;01mif[39;00m status [38;5;241m!=[39m CONTINUE:

File [1;32mC:\laragon\bin\python\python-3.10\lib\http\client.py:287[0m, in [0;36mHTTPResponse._read_status[1;34m(self)[0m
[0;32m    284[0m [38;5;28;01mif[39;00m [38;5;129;01mnot[39;00m line:
[0;32m    285[0m     [38;5;66;03m# Presumably, the server closed the connection before[39;00m
[0;32m    286[0m     [38;5;66;03m# sending a valid response.[39;00m
[1;32m--> 287[0m     [38;5;28;01mraise[39;00m RemoteDisconnected([38;5;124m"[39m[38;5;124mRemote end closed connection without[39m[38;5;124m"[39m
[0;32m    288[0m                              [38;5;124m"[39m[38;5;124m response[39m[38;5;124m"[39m)
[0;32m    289[0m [38;5;28;01mtry[39;00m:

[1;31mRemoteDisconnected[0m: Remote end closed connection without response

During handling of the above exception, another exception occurred:

[1;31mProtocolError[0m                             Traceback (most recent call last)
File [1;32mC:\laragon\bin\python\python-3.10\lib\site-packages\requests\adapters.py:644[0m, in [0;36mHTTPAdapter.send[1;34m(self, request, stream, timeout, verify, cert, proxies)[0m
[0;32m    643[0m [38;5;28;01mtry[39;00m:
[1;32m--> 644[0m     resp [38;5;241m=[39m [43mconn[49m[38;5;241;43m.[39;49m[43murlopen[49m[43m([49m
[0;32m    645[0m [43m        [49m[43mmethod[49m[38;5;241;43m=[39;49m[43mrequest[49m[38;5;241;43m.[39;49m[43mmethod[49m[43m,[49m
[0;32m    646[0m [43m        [49m[43murl[49m[38;5;241;43m=[39;49m[43murl[49m[43m,[49m
[0;32m    647[0m [43m        [49m[43mbody[49m[38;5;241;43m=[39;49m[43mrequest[49m[38;5;241;43m.[39;49m[43mbody[49m[43m,[49m
[0;32m    648[0m [43m        [49m[43mheaders[49m[38;5;241;43m=[39;49m[43mrequest[49m[38;5;241;43m.[39;49m[43mheaders[49m[43m,[49m
[0;32m    649[0m [43m        [49m[43mredirect[49m[38;5;241;43m=[39;49m[38;5;28;43;01mFalse[39;49;00m[43m,[49m
[0;32m    650[0m [43m        [49m[43massert_same_host[49m[38;5;241;43m=[39;49m[38;5;28;43;01mFalse[39;49;00m[43m,[49m
[0;32m    651[0m [43m        [49m[43mpreload_content[49m[38;5;241;43m=[39;49m[38;5;28;43;01mFalse[39;49;00m[43m,[49m
[0;32m    652[0m [43m        [49m[43mdecode_content[49m[38;5;241;43m=[39;49m[38;5;28;43;01mFalse[39;49;00m[43m,[49m
[0;32m    653[0m [43m        [49m[43mretries[49m[38;5;241;43m=[39;49m[38;5;28;43mself[39;49m[38;5;241;43m.[39;49m[43mmax_retries[49m[43m,[49m
[0;32m    654[0m [43m        [49m[43mtimeout[49m[38;5;241;43m=[39;49m[43mtimeout[49m[43m,[49m
[0;32m    655[0m [43m        [49m[43mchunked[49m[38;5;241;43m=[39;49m[43mchunked[49m[43m,[49m
[0;32m    656[0m [43m    [49m[43m)[49m
[0;32m    658[0m [38;5;28;01mexcept[39;00m (ProtocolError, [38;5;167;01mOSError[39;00m) [38;5;28;01mas[39;00m err:

File [1;32mC:\laragon\bin\python\python-3.10\lib\site-packages\urllib3\connectionpool.py:841[0m, in [0;36mHTTPConnectionPool.urlopen[1;34m(self, method, url, body, headers, retries, redirect, assert_same_host, timeout, pool_timeout, release_conn, chunked, body_pos, preload_content, decode_content, **response_kw)[0m
[0;32m    839[0m     new_e [38;5;241m=[39m ProtocolError([38;5;124m"[39m[38;5;124mConnection aborted.[39m[38;5;124m"[39m, new_e)
[1;32m--> 841[0m retries [38;5;241m=[39m [43mretries[49m[38;5;241;43m.[39;49m[43mincrement[49m[43m([49m
[0;32m    842[0m [43m    [49m[43mmethod[49m[43m,[49m[43m [49m[43murl[49m[43m,[49m[43m [49m[43merror[49m[38;5;241;43m=[39;49m[43mnew_e[49m[43m,[49m[43m [49m[43m_pool[49m[38;5;241;43m=[39;49m[38;5;28;43mself[39;49m[43m,[49m[43m [49m[43m_stacktrace[49m[38;5;241;43m=[39;49m[43msys[49m[38;5;241;43m.[39;49m[43mexc_info[49m[43m([49m[43m)[49m[43m[[49m[38;5;241;43m2[39;49m[43m][49m
[0;32m    843[0m [43m[49m[43m)[49m
[0;32m    844[0m retries[38;5;241m.[39msleep()

File [1;32mC:\laragon\bin\python\python-3.10\lib\site-packages\urllib3\util\retry.py:474[0m, in [0;36mRetry.increment[1;34m(self, method, url, response, error, _pool, _stacktrace)[0m
[0;32m    473[0m [38;5;28;01mif[39;00m read [38;5;129;01mis[39;00m [38;5;28;01mFalse[39;00m [38;5;129;01mor[39;00m method [38;5;129;01mis[39;00m [38;5;28;01mNone[39;00m [38;5;129;01mor[39;00m [38;5;129;01mnot[39;00m [38;5;28mself[39m[38;5;241m.[39m_is_method_retryable(method):
[1;32m--> 474[0m     [38;5;28;01mraise[39;00m [43mreraise[49m[43m([49m[38;5;28;43mtype[39;49m[43m([49m[43merror[49m[43m)[49m[43m,[49m[43m [49m[43merror[49m[43m,[49m[43m [49m[43m_stacktrace[49m[43m)[49m
[0;32m    475[0m [38;5;28;01melif[39;00m read [38;5;129;01mis[39;00m [38;5;129;01mnot[39;00m [38;5;28;01mNone[39;00m:

File [1;32mC:\laragon\bin\python\python-3.10\lib\site-packages\urllib3\util\util.py:38[0m, in [0;36mreraise[1;34m(tp, value, tb)[0m
[0;32m     37[0m [38;5;28;01mif[39;00m value[38;5;241m.[39m__traceback__ [38;5;129;01mis[39;00m [38;5;129;01mnot[39;00m tb:
[1;32m---> 38[0m     [38;5;28;01mraise[39;00m value[38;5;241m.[39mwith_traceback(tb)
[0;32m     39[0m [38;5;28;01mraise[39;00m value

File [1;32mC:\laragon\bin\python\python-3.10\lib\site-packages\urllib3\connectionpool.py:787[0m, in [0;36mHTTPConnectionPool.urlopen[1;34m(self, method, url, body, headers, retries, redirect, assert_same_host, timeout, pool_timeout, release_conn, chunked, body_pos, preload_content, decode_content, **response_kw)[0m
[0;32m    786[0m [38;5;66;03m# Make the request on the HTTPConnection object[39;00m
[1;32m--> 787[0m response [38;5;241m=[39m [38;5;28mself[39m[38;5;241m.[39m_make_request(
[0;32m    788[0m     conn,
[0;32m    789[0m     method,
[0;32m    790[0m     url,
[0;32m    791[0m     timeout[38;5;241m=[39mtimeout_obj,
[0;32m    792[0m     body[38;5;241m=[39mbody,
[0;32m    793[0m     headers[38;5;241m=[39mheaders,
[0;32m    794[0m     chunked[38;5;241m=[39mchunked,
[0;32m    795[0m     retries[38;5;241m=[39mretries,
[0;32m    796[0m     response_conn[38;5;241m=[39mresponse_conn,
[0;32m    797[0m     preload_content[38;5;241m=[39mpreload_content,
[0;32m    798[0m     decode_content[38;5;241m=[39mdecode_content,
[0;32m    799[0m     [38;5;241m*[39m[38;5;241m*[39mresponse_kw,
[0;32m    800[0m )
[0;32m    802[0m [38;5;66;03m# Everything went great![39;00m

File [1;32mC:\laragon\bin\python\python-3.10\lib\site-packages\urllib3\connectionpool.py:534[0m, in [0;36mHTTPConnectionPool._make_request[1;34m(self, conn, method, url, body, headers, retries, timeout, chunked, response_conn, preload_content, decode_content, enforce_content_length)[0m
[0;32m    533[0m [38;5;28;01mtry[39;00m:
[1;32m--> 534[0m     response [38;5;241m=[39m [43mconn[49m[38;5;241;43m.[39;49m[43mgetresponse[49m[43m([49m[43m)[49m
[0;32m    535[0m [38;5;28;01mexcept[39;00m (BaseSSLError, [38;5;167;01mOSError[39;00m) [38;5;28;01mas[39;00m e:

File [1;32mC:\laragon\bin\python\python-3.10\lib\site-packages\urllib3\connection.py:565[0m, in [0;36mHTTPConnection.getresponse[1;34m(self)[0m
[0;32m    564[0m [38;5;66;03m# Get the response from http.client.HTTPConnection[39;00m
[1;32m--> 565[0m httplib_response [38;5;241m=[39m [38;5;28;43msuper[39;49m[43m([49m[43m)[49m[38;5;241;43m.[39;49m[43mgetresponse[49m[43m([49m[43m)[49m
[0;32m    567[0m [38;5;28;01mtry[39;00m:

File [1;32mC:\laragon\bin\python\python-3.10\lib\http\client.py:1374[0m, in [0;36mHTTPConnection.getresponse[1;34m(self)[0m
[0;32m   1373[0m [38;5;28;01mtry[39;00m:
[1;32m-> 1374[0m     [43mresponse[49m[38;5;241;43m.[39;49m[43mbegin[49m[43m([49m[43m)[49m
[0;32m   1375[0m [38;5;28;01mexcept[39;00m [38;5;167;01mConnectionError[39;00m:

File [1;32mC:\laragon\bin\python\python-3.10\lib\http\client.py:318[0m, in [0;36mHTTPResponse.begin[1;34m(self)[0m
[0;32m    317[0m [38;5;28;01mwhile[39;00m [38;5;28;01mTrue[39;00m:
[1;32m--> 318[0m     version, status, reason [38;5;241m=[39m [38;5;28;43mself[39;49m[38;5;241;43m.[39;49m[43m_read_status[49m[43m([49m[43m)[49m
[0;32m    319[0m     [38;5;28;01mif[39;00m status [38;5;241m!=[39m CONTINUE:

File [1;32mC:\laragon\bin\python\python-3.10\lib\http\client.py:287[0m, in [0;36mHTTPResponse._read_status[1;34m(self)[0m
[0;32m    284[0m [38;5;28;01mif[39;00m [38;5;129;01mnot[39;00m line:
[0;32m    285[0m     [38;5;66;03m# Presumably, the server closed the connection before[39;00m
[0;32m    286[0m     [38;5;66;03m# sending a valid response.[39;00m
[1;32m--> 287[0m     [38;5;28;01mraise[39;00m RemoteDisconnected([38;5;124m"[39m[38;5;124mRemote end closed connection without[39m[38;5;124m"[39m
[0;32m    288[0m                              [38;5;124m"[39m[38;5;124m response[39m[38;5;124m"[39m)
[0;32m    289[0m [38;5;28;01mtry[39;00m:

[1;31mProtocolError[0m: ('Connection aborted.', RemoteDisconnected('Remote end closed connection without response'))

During handling of the above exception, another exception occurred:

[1;31mConnectionError[0m                           Traceback (most recent call last)
Cell [1;32mIn[4], line 6[0m
[0;32m      3[0m headers [38;5;241m=[39m {[38;5;124m"[39m[38;5;124mUser-Agent[39m[38;5;124m"[39m: [38;5;124m"[39m[38;5;124mMozilla/5.0 (Windows NT 10.0; Win64; x64) AppleWebKit/537.36 (KHTML, like Gecko) Chrome/140.0.0.0 Safari/537.36 Edg/140.0.0.0[39m[38;5;124m"[39m}
[0;32m      5[0m [38;5;66;03m# Ambil halaman utama[39;00m
[1;32m----> 6[0m response [38;5;241m=[39m [43mrequests[49m[38;5;241;43m.[39;49m[43mget[49m[43m([49m[43murl[49m[43m,[49m[43m [49m[43mheaders[49m[38;5;241;43m=[39;49m[43mheaders[49m[43m)[49m
[0;32m      7[0m soup [38;5;241m=[39m BeautifulSoup(response[38;5;241m.[39mtext, [38;5;124m"[39m[38;5;124mhtml.parser[39m[38;5;124m"[39m)
[0;32m      9[0m data [38;5;241m=[39m []

File [1;32mC:\laragon\bin\python\python-3.10\lib\site-packages\requests\api.py:73[0m, in [0;36mget[1;34m(url, params, **kwargs)[0m
[0;32m     62[0m [38;5;28;01mdef[39;00m[38;5;250m [39m[38;5;21mget[39m(url, params[38;5;241m=[39m[38;5;28;01mNone[39;00m, [38;5;241m*[39m[38;5;241m*[39mkwargs):
[0;32m     63[0m [38;5;250m    [39m[38;5;124mr[39m[38;5;124;03m"""Sends a GET request.[39;00m
[0;32m     64[0m 
[0;32m     65[0m [38;5;124;03m    :param url: URL for the new :class:`Request` object.[39;00m
[1;32m   (...)[0m
[0;32m     70[0m [38;5;124;03m    :rtype: requests.Response[39;00m
[0;32m     71[0m [38;5;124;03m    """[39;00m
[1;32m---> 73[0m     [38;5;28;01mreturn[39;00m request([38;5;124m"[39m[38;5;124mget[39m[38;5;124m"[39m, url, params[38;5;241m=[39mparams, [38;5;241m*[39m[38;5;241m*[39mkwargs)

File [1;32mC:\laragon\bin\python\python-3.10\lib\site-packages\requests\api.py:59[0m, in [0;36mrequest[1;34m(method, url, **kwargs)[0m
[0;32m     55[0m [38;5;66;03m# By using the 'with' statement we are sure the session is closed, thus we[39;00m
[0;32m     56[0m [38;5;66;03m# avoid leaving sockets open which can trigger a ResourceWarning in some[39;00m
[0;32m     57[0m [38;5;66;03m# cases, and look like a memory leak in others.[39;00m
[0;32m     58[0m [38;5;28;01mwith[39;00m sessions[38;5;241m.[39mSession() [38;5;28;01mas[39;00m session:
[1;32m---> 59[0m     [38;5;28;01mreturn[39;00m session[38;5;241m.[39mrequest(method[38;5;241m=[39mmethod, url[38;5;241m=[39murl, [38;5;241m*[39m[38;5;241m*[39mkwargs)

File [1;32mC:\laragon\bin\python\python-3.10\lib\site-packages\requests\sessions.py:589[0m, in [0;36mSession.request[1;34m(self, method, url, params, data, headers, cookies, files, auth, timeout, allow_redirects, proxies, hooks, stream, verify, cert, json)[0m
[0;32m    584[0m send_kwargs [38;5;241m=[39m {
[0;32m    585[0m     [38;5;124m"[39m[38;5;124mtimeout[39m[38;5;124m"[39m: timeout,
[0;32m    586[0m     [38;5;124m"[39m[38;5;124mallow_redirects[39m[38;5;124m"[39m: allow_redirects,
[0;32m    587[0m }
[0;32m    588[0m send_kwargs[38;5;241m.[39mupdate(settings)
[1;32m--> 589[0m resp [38;5;241m=[39m [38;5;28mself[39m[38;5;241m.[39msend(prep, [38;5;241m*[39m[38;5;241m*[39msend_kwargs)
[0;32m    591[0m [38;5;28;01mreturn[39;00m resp

File [1;32mC:\laragon\bin\python\python-3.10\lib\site-packages\requests\sessions.py:703[0m, in [0;36mSession.send[1;34m(self, request, **kwargs)[0m
[0;32m    700[0m start [38;5;241m=[39m preferred_clock()
[0;32m    702[0m [38;5;66;03m# Send the request[39;00m
[1;32m--> 703[0m r [38;5;241m=[39m adapter[38;5;241m.[39msend(request, [38;5;241m*[39m[38;5;241m*[39mkwargs)
[0;32m    705[0m [38;5;66;03m# Total elapsed time of the request (approximately)[39;00m
[0;32m    706[0m elapsed [38;5;241m=[39m preferred_clock() [38;5;241m-[39m start

File [1;32mC:\laragon\bin\python\python-3.10\lib\site-packages\requests\adapters.py:659[0m, in [0;36mHTTPAdapter.send[1;34m(self, request, stream, timeout, verify, cert, proxies)[0m
[0;32m    644[0m     resp [38;5;241m=[39m conn[38;5;241m.[39murlopen(
[0;32m    645[0m         method[38;5;241m=[39mrequest[38;5;241m.[39mmethod,
[0;32m    646[0m         url[38;5;241m=[39murl,
[1;32m   (...)[0m
[0;32m    655[0m         chunked[38;5;241m=[39mchunked,
[0;32m    656[0m     )
[0;32m    658[0m [38;5;28;01mexcept[39;00m (ProtocolError, [38;5;167;01mOSError[39;00m) [38;5;28;01mas[39;00m err:
[1;32m--> 659[0m     [38;5;28;01mraise[39;00m [38;5;167;01mConnectionError[39;00m(err, request[38;5;241m=[39mrequest)
[0;32m    661[0m [38;5;28;01mexcept[39;00m MaxRetryError [38;5;28;01mas[39;00m e:
[0;32m    662[0m     [38;5;28;01mif[39;00m [38;5;28misinstance[39m(e[38;5;241m.[39mreason, ConnectTimeoutError):
[0;32m    663[0m         [38;5;66;03m# TODO: Remove this in 3.0.0: see #2811[39;00m

[1;31mConnectionError[0m: ('Connection aborted.', RemoteDisconnected('Remote end closed connection without response'))

